Workbook

Sheet 封面_公布版
B3: 113年民眾日常使用運具狀況調查
B7: —平常日市話及手機調查—
B8: 統計表
B9: 說明：
B10: 1.本調查以全國22縣市市內電話及行動電話用戶為調查範圍。
B11: (105年以前僅調查市內電話用戶；98年調查未含金馬地區)
B12: 2.本報告之計算不含500公尺以下短行程。
B13: 3. 統計表中關聯性分析採「卡方檢定」(Chi-squareTest)。
B14: 4. ＊表示p＜0.05，即在95%的信心水準下，基本問題與題目問項有顯著相關。
B15: ＊＊表示p＜0.01，即在99%的信心水準下，基本問題與題目問項有顯著相關。
B16: ＊＊＊表示p＜0.001，即在99.9%的信心水準下，基本問題與題目問項有顯著相關。
B17: 5. # 表示細格期望值小於5的比例超過20%，卡方檢定結果僅作參考。
... B25: 汽車客運：包含國道客運、一般公路客運、遊覽車、市區公車、免費公車、
C26: 復康巴士及交通車。
B27: 計程車：包含一般計程車及多元化計程車。
B28: 其他公共運輸：包含飛機及渡輪。
B29: 自行車：包含公共自行車及其他自行車。
B30: 微型電動二輪車：原「電動自行車」，109年(含)前計入「自行車」，
C31: 自111年起更名並單獨列計。
B32: 機車：包含機車及共享機車。
B33: 自用小客車：包含自用小客車及共享汽車。
B34: 其他私人機動運具：包含自用大客車、自用小貨車及自用大貨車。

Sheet 目錄頁
A2: 目 錄
A4: A.民眾外出旅次概況
A5: 附表1 民眾外出比率
A6: 附表2 外出民眾旅次目的占比
A7: 附表3 民眾旅次次數分配
A8: 附表4 外出民眾旅次地點關係
A9: B. 民眾通勤學概況與地點關係
A10: 附表5 目前通勤或通學概況
A11: 附表6 通勤地點與住家地點關係
A12: 附表7 通學地點與住家地點關係
A13: C.外出民眾運具次數市占率
A14: 附表8 外出民眾運具次數市占率─按運具類別分
... A31: 附表23 通勤學民眾平均每一旅次花費時間

Sheet A
B15: A.民眾外出旅次概況

Sheet A01
A1: 附表1 民眾外出比率
A2: 《平日市話及手機》
A3: 調查對象為15歲以上民眾，以人的角度做分析。
G4: 單位：人；%
A5: 項目別 | D5: 樣本數 | E5: 總計
F6: 有外出 | G6: 沒有外出
A9: 全體 | D9: 34236 | E9: 100 | F9: 76.100253 | G9: 23.899747
A10: 居住縣市 | C10: ***
B11: 新北市 | D11: 5980.4971 | E11: 100 | F11: 76.904462 | G11: 23.095538
B12: 臺北市 | D12: 3636.2279 | E12: 100 | F12: 78.197226 | G12: 21.802774
B13: 桃園市 | D13: 3357.9805 | E13: 100 | F13: 79.072232 | G13: 20.927768
B14: 臺中市 | D14: 4082.8676 | E14: 100 | F14: 75.549277 | G14: 24.450723
B15: 臺南市 | D15: 2740.2932 | E15: 100 | F15: 78.05054 | G15: 21.94946
B16: 高雄市 | D16: 4037.8335 | E16: 100 | F16: 77.393542 | G16: 22.606458
B17: 宜蘭縣 | D17: 662.92573 | E17: 100 | F17: 73.706997 | G17: 26.293003
B18: 新竹縣 | D18: 837.20174 | E18: 100 | F18: 77.895473 | G18: 22.104527
B19: 苗栗縣 | D19: 784.8158 | E19: 100 | F19: 73.5869 | G19: 26.4131
B20: 彰化縣 | D20: 1775.9603 | E20: 100 | F20: 73.663823 | G20: 26.336177
B21: 南投縣 | D21: 705.41405 | E21: 100 | F21: 72.156152 | G21: 27.843848
B22: 雲林縣 | D22: 978.05836 | E22: 100 | F22: 71.206565 | G22: 28.793435
... B32: 連江縣 | D32: 20.841446 | E32: 100 | F32: 53.478966 | G32: 46.521034
A33: 是否為直轄市 | C33: ***
B34: 直轄市 | D34: 23835.7 | E34: 100 | F34: 77.389553 | G34: 22.610447
B35: 非直轄市 | D35: 10400.3 | E35: 100 | F35: 73.1454 | G35: 26.8546
A36: 性別 | C36: ***
B37: 男 | D37: 16749.695 | E37: 100 | F37: 77.328841 | G37: 22.671159
B38: 女 | D38: 17486.305 | E38: 100 | F38: 74.92342 | G38: 25.07658
A39: 年齡 | C39: ***
B40: 15-未滿18歲 | D40: 990.8975 | E40: 100 | F40: 81.323575 | G40: 18.676425
B41: 18-未滿20歲 | D41: 687.19909 | E41: 100 | F41: 66.299063 | G41: 33.700937
B42: 20-未滿30歲 | D42: 4595.9785 | E42: 100 | F42: 79.474196 | G42: 20.525804
B43: 30-未滿40歲 | D43: 5316.029 | E43: 100 | F43: 85.382858 | G43: 14.617142
B44: 40-未滿50歲 | D44: 6474.5931 | E44: 100 | F44: 85.011116 | G44: 14.988884
B45: 50-未滿60歲 | D45: 5835.4026 | E45: 100 | F45: 81.088415 | G45: 18.911585
B46: 60-未滿65歲 | D46: 2922.4243 | E46: 100 | F46: 72.398859 | G46: 27.601141
B47: 65歲及以上 | D47: 7413.4759 | E47: 100 | F47: 57.313023 | G47: 42.686977
A49: 教育程度 | C49: ***
B50: 小學及以下 | D50: 3395.0961 | E50: 100 | F50: 46.390879 | G50: 53.609121
B51: 國(初)中 | D51: 3014.9642 | E51: 100 | F51: 64.546916 | G51: 35.453084
B52: 高中(職) | D52: 9553.0689 | E52: 100 | F52: 74.095367 | G52: 25.904633
...

Sheet A02
A1: 附表2 外出民眾旅次目的占比
A2: 《平日市話及手機》
A3: 調查對象為昨天有外出的民眾，以旅次的角度做分析。
K4: 單位：旅次；%
A5: 項目別 | D5: 樣本數 | E5: 總計
F6: 通勤 | G6: 通學 | H6: 公(商)務 | I6: 購物 | J6: 家庭及 個人活動 | K6: 休閒
A9: 全體 | D9: 64959.853 | E9: 100 | F9: 44.892083 | G9: 4.5408001 | H9: 4.7431811 | I9: 17.073623 | J9: 16.840852 | K9: 11.909461
A10: 居住縣市 | C10: ***
B11: 新北市 | D11: 10221.054 | E11: 100 | F11: 53.398181 | G11: 4.3919525 | H11: 4.6358279 | I11: 12.902008 | J11: 15.628325 | K11: 9.0437058
B12: 臺北市 | D12: 6709.0416 | E12: 100 | F12: 44.228144 | G12: 5.23119 | H12: 6.0583306 | I12: 14.267577 | J12: 16.808786 | K12: 13.405973
B13: 桃園市 | D13: 6710.1983 | E13: 100 | F13: 47.128765 | G13: 4.7613296 | H13: 3.4215061 | I13: 16.046895 | J13: 16.585331 | K13: 12.056173
B14: 臺中市 | D14: 7037.842 | E14: 100 | F14: 48.740652 | G14: 5.0524952 | H14: 6.5334195 | I14: 15.066333 | J14: 13.594356 | K14: 11.012744
B15: 臺南市 | D15: 5905.2175 | E15: 100 | F15: 41.004151 | G15: 4.4685703 | H15: 4.002365 | I15: 20.801597 | J15: 16.127456 | K15: 13.595862
B16: 高雄市 | D16: 8427.3614 | E16: 100 | F16: 40.532969 | G16: 4.2459866 | H16: 4.425747 | I16: 20.254913 | J16: 18.036605 | K16: 12.503779
B17: 宜蘭縣 | D17: 1393.9732 | E17: 100 | F17: 37.25062 | G17: 3.2319064 | H17: 3.9314724 | I17: 18.080081 | J17: 22.826184 | K17: 14.679736
B18: 新竹縣 | D18: 1667.8871 | E18: 100 | F18: 48.044025 | G18: 5.3971345 | H18: 3.6465065 | I18: 16.771195 | J18: 15.892295 | K18: 10.248845
B19: 苗栗縣 | D19: 1563.9616 | E19: 100 | F19: 38.687869 | G19: 4.4074805 | H19: 4.5838131 | I19: 20.84 | J19: 19.793084 | K19: 11.687753
B20: 彰化縣 | D20: 2955.3726 | E20: 100 | F20: 53.308746 | G20: 4.6792075 | H20: 4.4291393 | I20: 16.000216 | J20: 12.5304 | K20: 9.0522914
B21: 南投縣 | D21: 1463.8493 | E21: 100 | F21: 37.975782 | G21: 2.5707704 | H21: 4.0241504 | I21: 20.691096 | J21: 19.073883 | K21: 15.664318
B22: 雲林縣 | D22: 2000.5111 | E22: 100 | F22: 36.798895 | G22: 5.0593494 | H22: 4.4109631 | I22: 19.706942 | J22: 18.988157 | K22: 15.035693
... B32: 連江縣 | D32: 27.230936 | E32: 100 | F32: 45.954833 | G32: 2.2523305 | H32: 12.839572 | I32: 10.847309 | J32: 11.326809 | K32: 16.779147
A33: 是否為直轄市 | C33: ***
B34: 直轄市 | D34: 45010.715 | E34: 100 | F34: 46.333655 | G34: 4.6581159 | H34: 4.8410918 | I34: 16.325882 | J34: 16.145305 | K34: 11.69595
B35: 非直轄市 | D35: 19949.138 | E35: 100 | F35: 41.639503 | G35: 4.2761036 | H35: 4.5222677 | I35: 18.760729 | J35: 18.410196 | K35: 12.3912
A36: 性別 | C36: ***
B37: 男 | D37: 32399.761 | E37: 100 | F37: 48.318248 | G37: 4.5765256 | H37: 7.2057729 | I37: 13.706772 | J37: 14.115295 | K37: 12.077387
B38: 女 | D38: 32560.092 | E38: 100 | F38: 41.48279 | G38: 4.5052506 | H38: 2.2927154 | I38: 20.423895 | J38: 19.552987 | K38: 11.742362
A39: 年齡 | C39: ***
B40: 15-未滿18歲 | D40: 1745.5889 | E40: 100 | F40: 1.5859244 | G40: 85.976694 | H40: 0.7419255 | I40: 2.6400053 | J40: 5.2175838 | K40: 3.837867
B41: 18-未滿20歲 | D41: 1064.9479 | E41: 100 | F41: 16.059831 | G41: 50.673779 | H41: 3.1123341 | I41: 9.4732842 | J41: 11.323421 | K41: 9.3573511
B42: 20-未滿30歲 | D42: 8619.0759 | E42: 100 | F42: 52.615192 | G42: 9.7302403 | H42: 4.3193095 | I42: 12.758439 | J42: 11.606836 | K42: 8.9699833
B43: 30-未滿40歲 | D43: 11493.445 | E43: 100 | F43: 61.346741 | G43: 0.11060663 | H43: 6.2198524 | I43: 11.730491 | J43: 15.345992 | K43: 5.2463168
B44: 40-未滿50歲 | D44: 14471.152 | E44: 100 | F44: 56.13769 | G44: 0.24725344 | H44: 6.1586469 | I44: 13.53374 | J44: 19.545719 | K44: 4.3769506
B45: 50-未滿60歲 | D45: 12114.528 | E45: 100 | F45: 50.812414 | G45: 0.10166445 | H45: 5.4340499 | I45: 18.642732 | J45: 14.951112 | K45: 10.058028
B46: 60-未滿65歲 | D46: 5287.3443 | E46: 100 | F46: 34.486494 | G46: 0.078891273 | H46: 4.210643 | I46: 26.673069 | J46: 17.48991 | K46: 17.060993
B47: 65歲及以上 | D47: 10163.772 | E47: 100 | F47: 12.539121 | G47: 0.055205026 | H47: 1.7290832 | I47: 28.226431 | J47: 23.607794 | K47: 33.842367
A49: 教育程度 | C49: ***
B50: 小學及以下 | D50: 3662.4814 | E50: 100 | F50: 13.279549 | G50: 0.015662939 | H50: 0.54293517 | I50: 30.684286 | J50: 18.847258 | K50: 36.630309
B51: 國(初)中 | D51: 4681.198 | E51: 100 | F51: 33.679471 | G51: 4.9219666 | H51: 2.5220041 | I51: 24.387281 | J51: 16.261427 | K51: 18.22785
B52: 高中(職) | D52: 17173.429 | E52: 100 | F52: 40.691261 | G52: 8.6211836 | H52: 4.2663508 | I52: 18.971064 | J52: 16.280786 | K52: 11.169355
...

Sheet A03
A1: 附表3 民眾旅次次數分配
A2: 《平日市話及手機》
A3: 調查對象為15歲以上民眾，以人的角度做分析。
P4: 單位：人；%
A5: 項目別 | D5: 樣本數 | F5: 平均數 | H5: 總計
I6: 0次 | J6: 1次 | K6: 2次 | L6: 3次 | M6: 4次 | N6: 5次 | O6: 6次 | P6: 7次及 以上
D7: 全體 民眾 | E7: 外出 民眾 | F7: 全體 民眾 | G7: 外出 民眾
A9: 全體 | D9: 34236 | E9: 26053.683 | F9: 1.8974136 | G9: 2.4933079 | H9: 100 | I9: 23.899747 | J9: 3.1482411 | K9: 53.159819 | L9: 7.4561504 | M9: 8.1264484 | N9: 1.7539527 | O9: 1.4486248 | P9: 1.0070164
A10: 居住縣市 | C10: ***
B11: 新北市 | D11: 5980.4971 | E11: 4599.2691 | F11: 1.7090644 | G11: 2.2223215 | H11: 100 | I11: 23.095538 | J11: 4.0883151 | K11: 59.031167 | L11: 8.9152439 | M11: 3.3578633 | N11: 0.87140283 | O11: 0.45143558 | P11: 0.18903417
B12: 臺北市 | D12: 3636.2279 | E12: 2843.4294 | F12: 1.8450553 | G12: 2.3594895 | H12: 100 | I12: 21.802774 | J12: 3.4924319 | K12: 56.22681 | L12: 9.3243365 | M12: 6.9295424 | N12: 1.0557349 | O12: 0.68024791 | P12: 0.48812185
B13: 桃園市 | D13: 3357.9805 | E13: 2655.2301 | F13: 1.9982839 | G13: 2.5271626 | H13: 100 | I13: 20.927768 | J13: 3.0051657 | K13: 55.030293 | L13: 6.789976 | M13: 9.3593106 | N13: 1.8122054 | O13: 2.183686 | P13: 0.89159469
B14: 臺中市 | D14: 4082.8676 | E14: 3084.577 | F14: 1.7237497 | G14: 2.2816231 | H14: 100 | I14: 24.450723 | J14: 5.47336 | K14: 55.504821 | L14: 7.568476 | M14: 4.494241 | N14: 1.2063985 | O14: 0.87575223 | P14: 0.42622806
B15: 臺南市 | D15: 2740.2932 | E15: 2138.8136 | F15: 2.1549583 | G15: 2.7609781 | H15: 100 | I15: 21.94946 | J15: 2.1300495 | K15: 48.205565 | L15: 7.5157396 | M15: 13.589194 | N15: 2.664993 | O15: 2.0418352 | P15: 1.9031637
B16: 高雄市 | D16: 4037.8335 | E16: 3125.0223 | F16: 2.0870998 | G16: 2.6967364 | H16: 100 | I16: 22.606458 | J16: 1.1421036 | K16: 51.256824 | L16: 6.3096088 | M16: 12.280993 | N16: 3.3151108 | O16: 1.8954176 | P16: 1.1934841
B17: 宜蘭縣 | D17: 662.92573 | E17: 488.62265 | F17: 2.1027592 | G17: 2.8528624 | H17: 100 | I17: 26.293003 | J17: 1.0391704 | K17: 48.567799 | L17: 4.5863939 | M17: 12.695595 | N17: 1.615649 | O17: 1.7646357 | P17: 3.4377537
B18: 新竹縣 | D18: 837.20174 | E18: 652.14226 | F18: 1.9922165 | G18: 2.5575511 | H18: 100 | I18: 22.104527 | J18: 2.3408616 | K18: 54.095755 | L18: 6.3605473 | M18: 10.412952 | N18: 1.8745117 | O18: 1.8988749 | P18: 0.91197115
B19: 苗栗縣 | D19: 784.8158 | E19: 577.52162 | F19: 1.9927754 | G19: 2.7080573 | H19: 100 | I19: 26.4131 | J19: 1.4775604 | K19: 49.145502 | L19: 8.1418743 | M19: 9.3559418 | N19: 1.2353293 | O19: 1.6241693 | P19: 2.6065232
B20: 彰化縣 | D20: 1775.9603 | E20: 1308.2402 | F20: 1.6640984 | G20: 2.2590443 | H20: 100 | I20: 26.336177 | J20: 4.620987 | K20: 55.416904 | L20: 7.3845904 | M20: 4.1081206 | N20: 0.86217891 | O20: 1.0130628 | P20: 0.25797927
B21: 南投縣 | D21: 705.41405 | E21: 508.99963 | F21: 2.0751633 | G21: 2.875934 | H21: 100 | I21: 27.843848 | J21: 0.96454662 | K21: 43.771768 | L21: 6.8907168 | M21: 12.788865 | N21: 2.1928009 | O21: 4.2381651 | P21: 1.3092891
B22: 雲林縣 | D22: 978.05836 | E22: 696.44176 | F22: 2.0453903 | G22: 2.8724743 | H22: 100 | I22: 28.793435 | J22: 1.3282313 | K22: 44.958578 | L22: 5.6910045 | M22: 12.142649 | N22: 1.4200851 | O22: 2.8218806 | P22: 2.8441371
... B32: 連江縣 | D32: 20.841446 | E32: 11.14579 | F32: 1.3065761 | G32: 2.4431589 | H32: 100 | I32: 46.521034 | J32: 2.3824189 | K32: 39.99094 | L32: 4.2517488 | M32: 4.2232244 | N32: 0.36300496 | O32: 1.208044 | P32: 1.0595856
A33: 是否為直轄市 | C33: ***
B34: 直轄市 | D34: 23835.7 | E34: 18446.341 | F34: 1.888374 | G34: 2.440089 | H34: 100 | I34: 22.610447 | J34: 3.3578335 | K34: 54.874102 | L34: 7.8452564 | M34: 7.6307322 | N34: 1.7096187 | O34: 1.2305202 | P34: 0.74149062
B35: 非直轄市 | D35: 10400.3 | E35: 7607.3412 | F35: 1.918131 | G35: 2.6223535 | H35: 100 | I35: 26.8546 | J35: 2.6678915 | K35: 49.230979 | L35: 6.5643865 | M35: 9.2625448 | N35: 1.8555587 | O35: 1.9484831 | P35: 1.6155559
A36: 性別 | C36: ***
B37: 男 | D37: 16749.695 | E37: 12952.345 | F37: 1.9343493 | G37: 2.5014591 | H37: 100 | I37: 22.671159 | J37: 3.2217457 | K37: 53.529403 | L37: 8.0453573 | M37: 8.2467455 | N37: 1.6035465 | O37: 1.6422214 | P37: 1.0398217
B38: 女 | D38: 17486.305 | E38: 13101.338 | F38: 1.8620338 | G38: 2.4852494 | H38: 100 | I38: 25.07658 | J38: 3.0778329 | K38: 52.805804 | L38: 6.8917638 | M38: 8.0112189 | N38: 1.8980231 | O38: 1.2631834 | P38: 0.97559308
A39: 年齡 | C39: ***
B40: 15-未滿18歲 | D40: 990.8975 | E40: 805.83327 | F40: 1.7616241 | G40: 2.1661912 | H40: 100 | I40: 18.676425 | J40: 1.4105391 | K40: 67.784923 | L40: 9.4927831 | M40: 2.4979471 | N40: 0.11240379 | O40: 0.024978371 | P40: 0
B41: 18-未滿20歲 | D41: 687.19909 | E41: 455.60656 | F41: 1.5496935 | G41: 2.3374289 | H41: 100 | I41: 33.700937 | J41: 4.9999397 | K41: 47.309945 | L41: 6.1910771 | M41: 4.8847826 | N41: 1.0851229 | O41: 1.0167715 | P41: 0.81142408
B42: 20-未滿30歲 | D42: 4595.9785 | E42: 3652.617 | F42: 1.8753517 | G42: 2.3596988 | H42: 100 | I42: 20.525804 | J42: 5.7454428 | K42: 54.609215 | L42: 9.4522459 | M42: 6.3269551 | N42: 1.6716949 | O42: 1.3504048 | P42: 0.31823708
B43: 30-未滿40歲 | D43: 5316.029 | E43: 4538.9775 | F43: 2.1620357 | G43: 2.5321661 | H43: 100 | I43: 14.617142 | J43: 2.4764823 | K43: 59.543875 | L43: 9.3448051 | M43: 8.7671717 | N43: 2.3102781 | O43: 1.5429294 | P43: 1.3973162
B44: 40-未滿50歲 | D44: 6474.5931 | E44: 5504.1239 | F44: 2.2350674 | G44: 2.6291472 | H44: 100 | I44: 14.988884 | J44: 2.5355826 | K44: 58.688304 | L44: 7.3849387 | M44: 9.6486162 | N44: 2.1924469 | O44: 2.461956 | P44: 2.099272
B45: 50-未滿60歲 | D45: 5835.4026 | E45: 4731.8355 | F45: 2.0760397 | G45: 2.5602174 | H45: 100 | I45: 18.911585 | J45: 2.4913509 | K45: 55.468329 | L45: 8.1361621 | M45: 9.9404043 | N45: 2.225768 | O45: 1.6951554 | P45: 1.1312459
B46: 60-未滿65歲 | D46: 2922.4243 | E46: 2115.8019 | F46: 1.8092323 | G46: 2.4989789 | H46: 100 | I46: 27.601141 | J46: 3.5706895 | K46: 49.168825 | L46: 6.6016014 | M46: 9.1878851 | N46: 2.2063302 | O46: 0.79864042 | P46: 0.86488756
B47: 65歲及以上 | D47: 7413.4759 | E47: 4248.8872 | F47: 1.370986 | G47: 2.392102 | H47: 100 | I47: 42.686977 | J47: 2.9660279 | K47: 41.198687 | L47: 4.5732096 | M47: 6.659757 | N47: 0.75475849 | O47: 0.84938702 | P47: 0.31119609
A49: 教育程度 | C49: ***
B50: 小學及以下 | D50: 3395.0961 | E50: 1575.0149 | F50: 1.0787563 | G50: 2.325363 | H50: 100 | I50: 53.609121 | J50: 2.356711 | K50: 35.068467 | L50: 2.5622698 | M50: 5.335624 | N50: 0.29477135 | O50: 0.66337106 | P50: 0.10966455
B51: 國(初)中 | D51: 3014.9642 | E51: 1946.0664 | F51: 1.5526546 | G51: 2.4054667 | H51: 100 | I51: 35.453084 | J51: 3.0523796 | K51: 47.391826 | L51: 4.0837496 | M51: 7.4345316 | N51: 1.0099182 | O51: 0.96900685 | P51: 0.60550384
...

Sheet A04
A1: 附表4 外出民眾旅次地點關係
A2: 《平日市話及手機》
A3: 調查對象為昨天有外出民眾，以旅次角度做分析。
I4: 單位：旅次；%
A5: 項目別 | D5: 樣本數 | E5: 總計
F6: 同縣市 | I6: 跨縣市
G7: 同鄉鎮市 | H7: 跨鄉鎮市
A9: 全體 | D9: 64959.853 | E9: 100 | F9: 84.3339 | G9: 53.047219 | H9: 31.286681 | I9: 15.6661
A10: 居住縣市 | C10: ***
B11: 新北市 | D11: 10221.054 | E11: 100 | F11: 63.964739 | G11: 42.511646 | H11: 21.453094 | I11: 36.035261
B12: 臺北市 | D12: 6709.0416 | E12: 100 | F12: 85.500587 | G12: 43.345663 | H12: 42.154924 | I12: 14.499413
B13: 桃園市 | D13: 6710.1983 | E13: 100 | F13: 83.407657 | G13: 57.821212 | H13: 25.586446 | I13: 16.592343
B14: 臺中市 | D14: 7037.842 | E14: 100 | F14: 92.157518 | G14: 53.313255 | H14: 38.844263 | I14: 7.8424816
B15: 臺南市 | D15: 5905.2175 | E15: 100 | F15: 95.0102 | G15: 53.839172 | H15: 41.171028 | I15: 4.9897999
B16: 高雄市 | D16: 8427.3614 | E16: 100 | F16: 91.824405 | G16: 52.603016 | H16: 39.221389 | I16: 8.1755947
B17: 宜蘭縣 | D17: 1393.9732 | E17: 100 | F17: 92.125115 | G17: 49.039686 | H17: 43.085429 | I17: 7.8748846
B18: 新竹縣 | D18: 1667.8871 | E18: 100 | F18: 76.080337 | G18: 58.382506 | H18: 17.69783 | I18: 23.919663
B19: 苗栗縣 | D19: 1563.9616 | E19: 100 | F19: 83.910357 | G19: 59.057752 | H19: 24.852605 | I19: 16.089643
B20: 彰化縣 | D20: 2955.3726 | E20: 100 | F20: 88.259639 | G20: 56.769535 | H20: 31.490104 | I20: 11.740361
B21: 南投縣 | D21: 1463.8493 | E21: 100 | F21: 87.113083 | G21: 71.001712 | H21: 16.111371 | I21: 12.886917
B22: 雲林縣 | D22: 2000.5111 | E22: 100 | F22: 91.799358 | G22: 67.352611 | H22: 24.446747 | I22: 8.2006419
... B32: 連江縣 | D32: 27.230936 | E32: 100 | F32: 96.666582 | G32: 94.821763 | H32: 1.8448192 | I32: 3.3334182
A33: 是否為直轄市 | C33: ***
B34: 直轄市 | D34: 45010.715 | E34: 100 | F34: 83.770706 | G34: 49.982774 | H34: 33.787932 | I34: 16.229294
B35: 非直轄市 | D35: 19949.138 | E35: 100 | F35: 85.60462 | G35: 59.961445 | H35: 25.643174 | I35: 14.39538
A36: 性別 | C36: ***
B37: 男 | D37: 32399.761 | E37: 100 | F37: 82.752317 | G37: 49.035482 | H37: 33.716835 | I37: 17.247683
B38: 女 | D38: 32560.092 | E38: 100 | F38: 85.907695 | G38: 57.039202 | H38: 28.868493 | I38: 14.092305
A39: 年齡 | C39: ***
B40: 15-未滿18歲 | D40: 1745.5889 | E40: 100 | F40: 83.73611 | G40: 43.505268 | H40: 40.230841 | I40: 16.26389
B41: 18-未滿20歲 | D41: 1064.9479 | E41: 100 | F41: 84.504357 | G41: 49.8344 | H41: 34.669957 | I41: 15.495643
B42: 20-未滿30歲 | D42: 8619.0759 | E42: 100 | F42: 81.193582 | G42: 48.342605 | H42: 32.850978 | I42: 18.806418
B43: 30-未滿40歲 | D43: 11493.445 | E43: 100 | F43: 82.410891 | G43: 48.578643 | H43: 33.832248 | I43: 17.589109
B44: 40-未滿50歲 | D44: 14471.152 | E44: 100 | F44: 84.346358 | G44: 49.744418 | H44: 34.60194 | I44: 15.653642
B45: 50-未滿60歲 | D45: 12114.528 | E45: 100 | F45: 83.733743 | G45: 51.350803 | H45: 32.38294 | I45: 16.266257
B46: 60-未滿65歲 | D46: 5287.3443 | E46: 100 | F46: 86.870497 | G46: 60.47193 | H46: 26.398567 | I46: 13.129503
B47: 65歲及以上 | D47: 10163.772 | E47: 100 | F47: 88.634379 | G47: 66.927518 | H47: 21.706861 | I47: 11.365621
A49: 教育程度 | C49: ***
B50: 小學及以下 | D50: 3662.4814 | E50: 100 | F50: 92.946963 | G50: 76.319038 | H50: 16.627925 | I50: 7.0530371
B51: 國(初)中 | D51: 4681.198 | E51: 100 | F51: 88.405406 | G51: 66.477784 | H51: 21.927623 | I51: 11.594594
...

Sheet B
B15: B. 民眾通勤學概況與地點關係

Sheet B05
A1: 附表5 目前通勤或通學概況
A2: 《平日市話及手機》
A3: 調查對象為15歲以上民眾，以人的角度做分析。
I4: 單位：人；%
A5: 項目別 | D5: 樣本數 | E5: 總計
F6: 僅上班 | G6: 僅上學 | H6: 兩者皆有 | I6: 兩者皆無
A9: 全體 | D9: 34236 | E9: 100 | F9: 59.927939 | G9: 5.5832409 | H9: 1.4183145 | I9: 33.070505
A10: 居住縣市 | C10: ***
B11: 新北市 | D11: 5980.4971 | E11: 100 | F11: 61.462285 | G11: 4.6971766 | H11: 1.3044191 | I11: 32.536119
B12: 臺北市 | D12: 3636.2279 | E12: 100 | F12: 55.632669 | G12: 5.5217636 | H12: 2.0640173 | I12: 36.78155
B13: 桃園市 | D13: 3357.9805 | E13: 100 | F13: 60.924789 | G13: 6.5552807 | H13: 1.0697419 | I13: 31.450188
B14: 臺中市 | D14: 4082.8676 | E14: 100 | F14: 60.243633 | G14: 6.8557718 | H14: 1.4384675 | I14: 31.462128
B15: 臺南市 | D15: 2740.2932 | E15: 100 | F15: 61.344748 | G15: 5.2887876 | H15: 1.6154448 | I15: 31.75102
B16: 高雄市 | D16: 4037.8335 | E16: 100 | F16: 59.684445 | G16: 5.7335926 | H16: 1.6193964 | I16: 32.962566
B17: 宜蘭縣 | D17: 662.92573 | E17: 100 | F17: 58.174594 | G17: 4.1556636 | H17: 1.808975 | I17: 35.860768
B18: 新竹縣 | D18: 837.20174 | E18: 100 | F18: 60.54996 | G18: 6.8757794 | H18: 1.7774986 | I18: 30.796762
B19: 苗栗縣 | D19: 784.8158 | E19: 100 | F19: 58.718022 | G19: 4.570466 | H19: 1.3630973 | I19: 35.348414
B20: 彰化縣 | D20: 1775.9603 | E20: 100 | F20: 62.361133 | G20: 4.6417711 | H20: 1.2072276 | I20: 31.789868
B21: 南投縣 | D21: 705.41405 | E21: 100 | F21: 58.882798 | G21: 4.0704707 | H21: 1.6340404 | I21: 35.412691
B22: 雲林縣 | D22: 978.05836 | E22: 100 | F22: 56.820245 | G22: 5.9499912 | H22: 0.84760665 | I22: 36.382157
... B32: 連江縣 | D32: 20.841446 | E32: 100 | F32: 80.268027 | G32: 1.816347 | H32: 0 | I32: 17.915626
A33: 是否為直轄市 | C33: ***
B34: 直轄市 | D34: 23835.7 | E34: 100 | F34: 59.973803 | G34: 5.698078 | H34: 1.4993142 | I34: 32.828805
B35: 非直轄市 | D35: 10400.3 | E35: 100 | F35: 59.822828 | G35: 5.3200542 | H35: 1.2326772 | I35: 33.624441
A36: 性別 | C36: ***
B37: 男 | D37: 16749.695 | E37: 100 | F37: 66.639842 | G37: 5.7460685 | H37: 1.6170449 | I37: 25.997045
B38: 女 | D38: 17486.305 | E38: 100 | F38: 53.498776 | G38: 5.4272724 | H38: 1.2279556 | I38: 39.845996
A39: 年齡 | C39: ***
B40: 15-未滿18歲 | D40: 990.8975 | E40: 100 | F40: 3.6774639 | G40: 87.198446 | H40: 6.6825467 | I40: 2.4415433
B41: 18-未滿20歲 | D41: 687.19909 | E41: 100 | F41: 19.928688 | G41: 58.660015 | H41: 12.216044 | I41: 9.1952528
B42: 20-未滿30歲 | D42: 4595.9785 | E42: 100 | F42: 70.575117 | G42: 13.389983 | H42: 6.7426218 | I42: 9.2922776
B43: 30-未滿40歲 | D43: 5316.029 | E43: 100 | F43: 89.146398 | G43: 0.037001856 | H43: 0.13329489 | I43: 10.683305
B44: 40-未滿50歲 | D44: 6474.5931 | E44: 100 | F44: 85.348829 | G44: 0.17160994 | H44: 0.1531101 | I44: 14.326451
B45: 50-未滿60歲 | D45: 5835.4026 | E45: 100 | F45: 72.452075 | G45: 0.10037027 | H45: 0.061673903 | I45: 27.385881
B46: 60-未滿65歲 | D46: 2922.4243 | E46: 100 | F46: 48.825085 | G46: 0.071725265 | H46: 0.15930563 | I46: 50.943884
B47: 65歲及以上 | D47: 7413.4759 | E47: 100 | F47: 15.918825 | G47: 0.10640215 | H47: 0.0035774108 | I47: 83.971195
A49: 教育程度 | C49: ***
B50: 小學及以下 | D50: 3395.0961 | E50: 100 | F50: 14.765533 | G50: 0.14374709 | H50: 0 | I50: 85.09072
B51: 國(初)中 | D51: 3014.9642 | E51: 100 | F51: 43.066385 | G51: 4.4392616 | H51: 0.04484318 | I51: 52.449511
B52: 高中(職) | D52: 9553.0689 | E52: 100 | F52: 56.926658 | G52: 8.7263939 | H52: 0.96733298 | I52: 33.379615
...

Sheet B06
A1: 附表6 通勤地點與住家地點關係
A2: 《平日市話及手機》
A3: 調查對象為目前有在工作民眾，以人的角度做分析。
I4: 單位：人；%
A5: 項目別 | D5: 樣本數 | E5: 總計
F6: 同縣市 | I6: 跨縣市
G7: 同鄉鎮市 | H7: 跨鄉鎮市
A9: 全體 | D9: 21002.503 | E9: 100 | F9: 83.093519 | G9: 49.216293 | H9: 33.877226 | I9: 16.906481
A10: 居住縣市 | C10: ***
B11: 新北市 | D11: 3753.7609 | E11: 100 | F11: 62.993748 | G11: 40.85666 | H11: 22.137087 | I11: 37.006252
B12: 臺北市 | D12: 2097.983 | E12: 100 | F12: 86.152611 | G12: 40.98212 | H12: 45.170492 | I12: 13.847389
B13: 桃園市 | D13: 2081.7643 | E13: 100 | F13: 81.225619 | G13: 51.524965 | H13: 29.700654 | I13: 18.774381
B14: 臺中市 | D14: 2518.3985 | E14: 100 | F14: 92.824302 | G14: 52.070984 | H14: 40.753318 | I14: 7.1756979
B15: 臺南市 | D15: 1725.2939 | E15: 100 | F15: 96.630851 | G15: 47.049012 | H15: 49.581839 | I15: 3.3691493
B16: 高雄市 | D16: 2475.347 | E16: 100 | F16: 92.031185 | G16: 44.246308 | H16: 47.784877 | I16: 7.9688145
B17: 宜蘭縣 | D17: 397.64651 | E17: 100 | F17: 91.466979 | G17: 50.473236 | H17: 40.993743 | I17: 8.5330213
B18: 新竹縣 | D18: 521.80656 | E18: 100 | F18: 72.296591 | G18: 50.899525 | H18: 21.397067 | I18: 27.703409
B19: 苗栗縣 | D19: 471.52612 | E19: 100 | F19: 77.752082 | G19: 49.822972 | H19: 27.92911 | I19: 22.247918
B20: 彰化縣 | D20: 1128.9488 | E20: 100 | F20: 86.770711 | G20: 56.951406 | H20: 29.819305 | I20: 13.229289
B21: 南投縣 | D21: 426.89428 | E21: 100 | F21: 86.130082 | G21: 70.188907 | H21: 15.941175 | I21: 13.869918
B22: 雲林縣 | D22: 564.02524 | E22: 100 | F22: 90.3147 | G22: 65.166787 | H22: 25.147913 | I22: 9.6853002
... B32: 連江縣 | D32: 16.729018 | E32: 100 | F32: 100 | G32: 100 | H32: 0 | I32: 0
A33: 是否為直轄市 | C33: ***
B34: 直轄市 | D34: 14652.548 | E34: 100 | F34: 82.893237 | G34: 45.619547 | H34: 37.273689 | I34: 17.106763
B35: 非直轄市 | D35: 6349.9559 | E35: 100 | F35: 83.555672 | G35: 57.515797 | H35: 26.039875 | I35: 16.444328
A36: 性別 | C36: ***
B37: 男 | D37: 11432.82 | E37: 100 | F37: 81.393442 | G37: 46.986768 | H37: 34.406674 | I37: 18.606558
B38: 女 | D38: 9569.6833 | E38: 100 | F38: 85.124587 | G38: 51.879887 | H38: 33.2447 | I38: 14.875413
A39: 年齡 | C39: ***
B40: 15-未滿18歲 | D40: 102.65709 | E40: 100 | F40: 90.74428 | G40: 81.419576 | H40: 9.3247038 | I40: 9.25572
B41: 18-未滿20歲 | D41: 220.89831 | E41: 100 | F41: 82.013679 | G41: 55.371822 | H41: 26.641858 | I41: 17.986321
B42: 20-未滿30歲 | D42: 3553.5067 | E42: 100 | F42: 84.99171 | G42: 48.443016 | H42: 36.548694 | I42: 15.00829
B43: 30-未滿40歲 | D43: 4746.1344 | E43: 100 | F43: 81.095252 | G43: 46.16451 | H43: 34.930742 | I43: 18.904748
B44: 40-未滿50歲 | D44: 5535.9027 | E44: 100 | F44: 83.033148 | G44: 47.471055 | H44: 35.562093 | I44: 16.966852
B45: 50-未滿60歲 | D45: 4231.4692 | E45: 100 | F45: 82.085683 | G45: 47.29335 | H45: 34.792333 | I45: 17.914317
B46: 60-未滿65歲 | D46: 1431.5317 | E46: 100 | F46: 84.355547 | G46: 56.836811 | H46: 27.518736 | I46: 15.644453
B47: 65歲及以上 | D47: 1180.4035 | E47: 100 | F47: 87.315929 | G47: 65.698537 | H47: 21.617392 | I47: 12.684071
A49: 教育程度
B50: 小學及以下 | D50: 501.30404 | E50: 100 | F50: 88.223963 | G50: 72.867229 | H50: 15.356734 | I50: 11.776037
B51: 國(初)中 | D51: 1299.7881 | E51: 100 | F51: 87.534971 | G51: 60.946879 | H51: 26.588093 | I51: 12.465029
...

Sheet B07
A1: 附表7 通學地點與住家地點關係
A2: 《平日市話及手機》
A3: 調查對象為目前有在上學民眾，以人的角度做分析。
I4: 單位：人；%
A5: 項目別 | D5: 樣本數 | E5: 總計
F6: 同縣市 | I6: 跨縣市
G7: 同鄉鎮市 | H7: 跨鄉鎮市
A9: 全體 | D9: 2397.0525 | E9: 100 | F9: 83.513703 | G9: 51.156716 | H9: 32.356987 | I9: 16.486297
A10: 居住縣市 | C10: ***
B11: 新北市 | D11: 358.92526 | E11: 100 | F11: 58.976815 | G11: 34.277928 | H11: 24.698887 | I11: 41.023185
B12: 臺北市 | D12: 275.83628 | E12: 100 | F12: 87.020348 | G12: 57.23262 | H12: 29.787729 | I12: 12.979652
B13: 桃園市 | D13: 256.04677 | E13: 100 | F13: 87.294408 | G13: 52.895849 | H13: 34.398559 | I13: 12.705592
B14: 臺中市 | D14: 338.64281 | E14: 100 | F14: 95.641559 | G14: 57.695126 | H14: 37.946432 | I14: 4.3584413
B15: 臺南市 | D15: 189.19621 | E15: 100 | F15: 94.46706 | G15: 55.349636 | H15: 39.117424 | I15: 5.53294
B16: 高雄市 | D16: 296.90145 | E16: 100 | F16: 95.819356 | G16: 51.919129 | H16: 43.900227 | I16: 4.180644
B17: 宜蘭縣 | D17: 39.541124 | E17: 100 | F17: 90.25648 | G17: 47.053221 | H17: 43.203258 | I17: 9.7435204
B18: 新竹縣 | D18: 72.445394 | E18: 100 | F18: 59.50212 | G18: 40.631933 | H18: 18.870186 | I18: 40.49788
B19: 苗栗縣 | D19: 46.567543 | E19: 100 | F19: 88.4515 | G19: 54.068706 | H19: 34.382794 | I19: 11.5485
B20: 彰化縣 | D20: 103.87589 | E20: 100 | F20: 64.546814 | G20: 24.178123 | H20: 40.368692 | I20: 35.453186
B21: 南投縣 | D21: 40.240422 | E21: 100 | F21: 84.903665 | G21: 63.083784 | H21: 21.819881 | I21: 15.096335
B22: 雲林縣 | D22: 66.484474 | E22: 100 | F22: 85.691771 | G22: 60.639855 | H22: 25.051916 | I22: 14.308229
... B32: 連江縣 | D32: 0.37855299 | E32: 100 | F32: 100 | G32: 56.974637 | H32: 43.025363 | I32: 0
A33: 是否為直轄市 | C33: ***
B34: 直轄市 | D34: 1715.5488 | E34: 100 | F34: 85.239856 | G34: 50.746854 | H34: 34.493002 | I34: 14.760144
B35: 非直轄市 | D35: 681.50374 | E35: 100 | F35: 79.168461 | G35: 52.18846 | H35: 26.980001 | I35: 20.831539
A36: 性別 | C36: ***
B37: 男 | D37: 1233.299 | E37: 100 | F37: 87.831103 | G37: 53.534076 | H37: 34.297028 | I37: 12.168897
B38: 女 | D38: 1163.7535 | E38: 100 | F38: 78.938297 | G38: 48.637286 | H38: 30.301011 | I38: 21.061703
A39: 年齡 | C39: ***
B40: 15-未滿18歲 | D40: 930.26441 | E40: 100 | F40: 84.961039 | G40: 46.292696 | H40: 38.668343 | I40: 15.038961
B41: 18-未滿20歲 | D41: 487.05963 | E41: 100 | F41: 83.937742 | G41: 52.863234 | H41: 31.074508 | I41: 16.062258
B42: 20-未滿30歲 | D42: 925.29021 | E42: 100 | F42: 81.666628 | G42: 55.444424 | H42: 26.222204 | I42: 18.333372
B43: 30-未滿40歲 | D43: 9.0530246 | E43: 100 | F43: 74.234179 | G43: 42.551722 | H43: 31.682458 | I43: 25.765821
B44: 40-未滿50歲 | D44: 21.024301 | E44: 100 | F44: 78.547384 | G44: 19.49004 | H44: 59.057344 | I44: 21.452616
B45: 50-未滿60歲 | D45: 9.4559299 | E45: 100 | F45: 93.965942 | G45: 52.270321 | H45: 41.695621 | I45: 6.0340582
B46: 60-未滿65歲 | D46: 6.751703 | E46: 100 | F46: 100 | G46: 67.111502 | H46: 32.888498 | I46: 0
B47: 65歲及以上 | D47: 8.153308 | E47: 100 | F47: 100 | G47: 94.291674 | H47: 5.7083263 | I47: 0
A49: 教育程度 | C49: ***
B50: 小學及以下 | D50: 4.8803517 | E50: 100 | F50: 100 | G50: 95.897695 | H50: 4.1023054 | I50: 0
B51: 國(初)中 | D51: 135.19415 | E51: 100 | F51: 96.581484 | G51: 81.719364 | H51: 14.86212 | I51: 3.4185161
...

Sheet C
B15: Ｃ.外出民眾運具次數市占率

Sheet C08
A1: 附表8 外出民眾運具次數市占率─按運具類別分
A2: 《平日市話及手機》
A3: 調查對象為昨天有外出民眾，以運具次數角度做分析。
H4: 單位：運具次數；%
A5: 項目別 | D5: 樣本數 | E5: 總計
F6: 公共 運輸工具 | G6: 非機動 運輸工具 | H6: 私人機動 運輸工具
A9: 全體 | D9: 70610.93 | E9: 100 | F9: 15.205768 | G9: 12.801645 | H9: 71.992587
A10: 居住縣市 | C10: ***
B11: 新北市 | D11: 11825.78 | E11: 100 | F11: 29.022313 | G11: 16.180043 | H11: 54.797644
B12: 臺北市 | D12: 7971.3183 | E12: 100 | F12: 38.331318 | G12: 24.710046 | H12: 36.958636
B13: 桃園市 | D13: 7305.4333 | E13: 100 | F13: 12.943646 | G13: 14.005143 | H13: 73.051211
B14: 臺中市 | D14: 7339.5437 | E14: 100 | F14: 9.0082473 | G14: 9.3891125 | H14: 81.60264
B15: 臺南市 | D15: 6151.9164 | E15: 100 | F15: 4.9273885 | G15: 9.9964492 | H15: 85.076162
B16: 高雄市 | D16: 9200.7959 | E16: 100 | F16: 10.190652 | G16: 8.6028633 | H16: 81.206485
B17: 宜蘭縣 | D17: 1500.8651 | E17: 100 | F17: 8.3201713 | G17: 11.171989 | H17: 80.50784
B18: 新竹縣 | D18: 1737.1933 | E18: 100 | F18: 6.9230858 | G18: 10.858949 | H18: 82.217966
B19: 苗栗縣 | D19: 1660.7303 | E19: 100 | F19: 6.8143924 | G19: 9.5460152 | H19: 83.639592
B20: 彰化縣 | D20: 3032.284 | E20: 100 | F20: 3.4478565 | G20: 7.4566209 | H20: 89.095523
B21: 南投縣 | D21: 1486.6441 | E21: 100 | F21: 3.325239 | G21: 9.4733741 | H21: 87.201387
B22: 雲林縣 | D22: 2042.8752 | E22: 100 | F22: 3.8018243 | G22: 9.7626788 | H22: 86.435497
... B32: 連江縣 | D32: 30.505973 | E32: 100 | F32: 9.9172226 | G32: 15.81549 | H32: 74.267288
A33: 是否為直轄市 | C33: ***
B34: 直轄市 | D34: 49794.788 | E34: 100 | F34: 18.747203 | G34: 14.061496 | H34: 67.191301
B35: 非直轄市 | D35: 20816.143 | E35: 100 | F35: 6.7342169 | G35: 9.787925 | H35: 83.477858
A36: 性別 | C36: ***
B37: 男 | D37: 34519.188 | E37: 100 | F37: 11.031506 | G37: 10.781281 | H37: 78.187213
B38: 女 | D38: 36091.743 | E38: 100 | F38: 19.198152 | G38: 14.733979 | H38: 66.067868
A39: 年齡 | C39: ***
B40: 15-未滿18歲 | D40: 2212.2927 | E40: 100 | F40: 43.154489 | G40: 30.567669 | H40: 26.277841
B41: 18-未滿20歲 | D41: 1244.5921 | E41: 100 | F41: 27.399422 | G41: 14.491152 | H41: 58.109426
B42: 20-未滿30歲 | D42: 9701.8898 | E42: 100 | F42: 17.747568 | G42: 9.3151944 | H42: 72.937237
B43: 30-未滿40歲 | D43: 12380.778 | E43: 100 | F43: 12.864226 | G43: 7.3100272 | H43: 79.825747
B44: 40-未滿50歲 | D44: 15486.216 | E44: 100 | F44: 11.010597 | G44: 7.7829253 | H44: 81.206478
B45: 50-未滿60歲 | D45: 12901.869 | E45: 100 | F45: 11.818981 | G45: 9.640612 | H45: 78.540407
B46: 60-未滿65歲 | D46: 5681.6279 | E46: 100 | F46: 12.848816 | G46: 14.4996 | H46: 72.651584
B47: 65歲及以上 | D47: 11001.665 | E47: 100 | F47: 19.693951 | G47: 28.187164 | H47: 52.118885
A49: 教育程度 | C49: ***
B50: 小學及以下 | D50: 3786.5522 | E50: 100 | F50: 12.806226 | G50: 36.221089 | H50: 50.972685
B51: 國(初)中 | D51: 4923.441 | E51: 100 | F51: 10.327877 | G51: 15.628747 | H51: 74.043377
B52: 高中(職) | D52: 18441.555 | E52: 100 | F52: 13.352754 | G52: 11.748445 | H52: 74.898801
...

Sheet C09
A1: 附表9 外出民眾運具次數市占率─按性別分
A2: 《平日市話及手機》
A3: 調查對象為昨天有外出民眾，以運具次數角度做分析。
M4: 單位：運具次數；%
A5: 項目別 | D5: 男性 | I5: 女性
D6: 樣本數 | E6: 總計 | I6: 樣本數 | J6: 總計
F7: 公共 運輸 | G7: 非機動 運具 | H7: 私人機動運具 | K7: 公共 運輸 | L7: 非機動 運具 | M7: 私人機動運具
A9: 全體 | D9: 34519.188 | E9: 100 | F9: 11.031506 | G9: 10.781281 | H9: 78.187213 | I9: 36091.743 | J9: 100 | K9: 19.198152 | L9: 14.733979 | M9: 66.067868
A10: 居住縣市
B11: 新北市 | D11: 5745.1116 | E11: 100 | F11: 18.022899 | G11: 10.299361 | H11: 71.677739 | I11: 6080.6684 | J11: 100 | K11: 39.414732 | L11: 21.736203 | M11: 38.849064
B12: 臺北市 | D12: 3585.7862 | E12: 100 | F12: 28.335742 | G12: 19.954017 | H12: 51.710241 | I12: 4385.5321 | J12: 100 | K12: 46.504099 | L12: 28.598766 | M12: 24.897135
B13: 桃園市 | D13: 3431.2778 | E13: 100 | F13: 6.6166673 | G13: 10.258302 | H13: 83.125031 | I13: 3874.1555 | J13: 100 | K13: 18.54735 | L13: 17.323661 | M13: 64.128989
B14: 臺中市 | D14: 3775.949 | E14: 100 | F14: 8.8052521 | G14: 8.9269017 | H14: 82.267846 | I14: 3563.5947 | J14: 100 | K14: 9.2233391 | L14: 9.8788664 | M14: 80.897795
B15: 臺南市 | D15: 2969.547 | E15: 100 | F15: 3.0855791 | G15: 9.3025519 | H15: 87.611869 | I15: 3182.3693 | J15: 100 | K15: 6.6460261 | L15: 10.643942 | M15: 82.710032
B16: 高雄市 | D16: 4586.6522 | E16: 100 | F16: 12.00996 | G16: 8.6737585 | H16: 79.316281 | I16: 4614.1437 | J16: 100 | K16: 8.3821828 | L16: 8.5323906 | M16: 83.085427
B17: 宜蘭縣 | D17: 689.65949 | E17: 100 | F17: 5.255287 | G17: 14.59442 | H17: 80.150293 | I17: 811.20557 | J17: 100 | K17: 10.925832 | L17: 8.2623543 | M17: 80.811814
B18: 新竹縣 | D18: 838.18412 | E18: 100 | F18: 6.4556988 | G18: 12.78212 | H18: 80.762181 | I18: 899.0092 | J18: 100 | K18: 7.3588504 | L18: 9.0658946 | M18: 83.575255
B19: 苗栗縣 | D19: 832.96832 | E19: 100 | F19: 8.3074176 | G19: 8.7139021 | H19: 82.97868 | I19: 827.76198 | J19: 100 | K19: 5.3119766 | L19: 10.383362 | M19: 84.304661
B20: 彰化縣 | D20: 1609.1897 | E20: 100 | F20: 3.1115781 | G20: 8.4607409 | H20: 88.427681 | I20: 1423.0943 | J20: 100 | K20: 3.8281094 | L20: 6.321194 | M20: 89.850697
B21: 南投縣 | D21: 795.64609 | E21: 100 | F21: 3.2062947 | G21: 7.2404928 | H21: 89.553213 | I21: 690.99801 | J21: 100 | K21: 3.4621969 | L21: 12.044414 | M21: 84.493389
B22: 雲林縣 | D22: 1029.5473 | E22: 100 | F22: 3.2878483 | G22: 11.841384 | H22: 84.870768 | I22: 1013.328 | J22: 100 | K22: 4.3240269 | L22: 7.650702 | M22: 88.025271
... B32: 連江縣 | D32: 17.393032 | E32: 100 | F32: 3.8397839 | G32: 17.20838 | H32: 78.951836 | I32: 13.112941 | J32: 100 | K32: 17.97835 | L32: 13.967956 | M32: 68.053693
A33: 是否為直轄市
B34: 直轄市 | D34: 24094.324 | E34: 100 | F34: 13.503163 | G34: 11.082955 | H34: 75.413882 | I34: 25700.464 | J34: 100 | K34: 23.663519 | L34: 16.853895 | M34: 59.482587
B35: 非直轄市 | D35: 10424.864 | E35: 100 | F35: 5.318924 | G35: 10.084042 | H35: 84.597034 | I35: 10391.279 | J35: 100 | K35: 8.1540841 | L35: 9.4908507 | M35: 82.355065
A36: 年齡
B37: 15-未滿18歲 | D37: 1111.434 | E37: 100 | F37: 39.889341 | G37: 35.417311 | H37: 24.693348 | I37: 1100.8587 | J37: 100 | K37: 46.451004 | L37: 25.67144 | M37: 27.877556
B38: 18-未滿20歲 | D38: 639.47386 | E38: 100 | F38: 24.871755 | G38: 17.089655 | H38: 58.03859 | I38: 605.11827 | J38: 100 | K38: 30.070597 | L38: 11.74512 | M38: 58.184283
B39: 20-未滿30歲 | D39: 5094.8533 | E39: 100 | F39: 15.962635 | G39: 8.0008288 | H39: 76.036536 | I39: 4607.0364 | J39: 100 | K39: 19.721499 | L39: 10.768732 | M39: 69.509769
B40: 30-未滿40歲 | D40: 6139.1807 | E40: 100 | F40: 5.9242335 | G40: 5.9907013 | H40: 88.085065 | I40: 6241.597 | J40: 100 | K40: 19.690342 | L40: 8.6077047 | M40: 71.701954
B41: 40-未滿50歲 | D41: 7519.5837 | E41: 100 | F41: 9.5577138 | G41: 5.028564 | H41: 85.413722 | I41: 7966.6319 | J41: 100 | K41: 12.381951 | L41: 10.382725 | M41: 77.235324
B42: 50-未滿60歲 | D42: 6319.4904 | E42: 100 | F42: 6.7282824 | G42: 6.9505756 | H42: 86.321142 | I42: 6582.379 | J42: 100 | K42: 16.706365 | L42: 12.223213 | M42: 71.070422
B43: 60-未滿65歲 | D43: 2644.3833 | E43: 100 | F43: 8.468301 | G43: 13.383919 | H43: 78.14778 | I43: 3037.2446 | J43: 100 | K43: 16.662721 | L43: 15.47097 | M43: 67.866309
B44: 65歲及以上 | D44: 5050.7884 | E44: 100 | F44: 13.082991 | G44: 25.183913 | H44: 61.733096 | I44: 5950.8766 | J44: 100 | K44: 25.304983 | L44: 30.736164 | M44: 43.958853
A46: 教育程度
B47: 小學及以下 | D47: 1287.032 | E47: 100 | F47: 5.27373 | G47: 31.053833 | H47: 63.672437 | I47: 2499.5202 | J47: 100 | K47: 16.684795 | L47: 38.88177 | M47: 44.433435
B48: 國(初)中 | D48: 2690.8405 | E48: 100 | F48: 6.2061509 | G48: 14.869856 | H48: 78.923993 | I48: 2232.6005 | J48: 100 | K48: 15.295585 | L48: 16.543399 | M48: 68.161017
B49: 高中(職) | D49: 9507.8827 | E49: 100 | F49: 10.468061 | G49: 10.379431 | H49: 79.152507 | I49: 8933.6722 | J49: 100 | K49: 16.422861 | L49: 13.205452 | M49: 70.371688
B50: 專科 | D50: 3655.9349 | E50: 100 | F50: 6.7800124 | G50: 11.672606 | H50: 81.547381 | I50: 4266.1229 | J50: 100 | K50: 18.947649 | L50: 12.714571 | M50: 68.33778
B51: 大學 | D51: 12250.244 | E51: 100 | F51: 11.646346 | G51: 9.2127702 | H51: 79.140884 | I51: 14044.361 | J51: 100 | K51: 21.141531 | L51: 12.50197 | M51: 66.356499
...

Sheet C10
A1: 附表10 外出民眾運具次數之公共運輸市占率─按縣市別分 | O1: 附表10 外出民眾運具次數之公共運輸市占率─按縣市別分(續)
A2: 《平日市話及手機》 | O2: 《平日市話及手機》
A3: 調查對象為昨天有外出民眾，以運具次數角度做分析。 | O3: 調查對象為昨天有外出民眾，以運具次數角度做分析。
N4: 單位：% | Y4: 單位：%
A5: 項目別 | D5: 新北市 | E5: 臺北市 | F5: 桃園市 | G5: 臺中市 | H5: 臺南市 | I5: 高雄市 | J5: 宜蘭縣 | K5: 新竹縣 | L5: 苗栗縣 | M5: 彰化縣 | N5: 南投縣 | O5: 雲林縣 | P5: 嘉義縣 | Q5: 屏東縣 | R5: 臺東縣 | S5: 花蓮縣 | T5: 澎湖縣 | U5: 基隆市 | V5: 新竹市 | W5: 嘉義市 | X5: 金門縣 | Y5: 連江縣
A9: 全體 | D9: 29.022313 | E9: 38.331318 | F9: 12.943646 | G9: 9.0082473 | H9: 4.9273885 | I9: 10.190652 | J9: 8.3201713 | K9: 6.9230858 | L9: 6.8143924 | M9: 3.4478565 | N9: 3.325239 | O9: 3.8018243 | P9: 4.4064474 | Q9: 4.0721625 | R9: 5.4019043 | S9: 5.0398142 | T9: 5.6060168 | U9: 33.371024 | V9: 6.8478047 | W9: 4.1896618 | X9: 5.9422513 | Y9: 9.9172226
A10: 性別
B11: 男 | D11: 18.022899 | E11: 28.335742 | F11: 6.6166673 | G11: 8.8052521 | H11: 3.0855791 | I11: 12.00996 | J11: 5.255287 | K11: 6.4556988 | L11: 8.3074176 | M11: 3.1115781 | N11: 3.2062947 | O11: 3.2878483 | P11: 1.6119409 | Q11: 3.4747751 | R11: 5.2855455 | S11: 4.0882216 | T11: 5.7304527 | U11: 24.290903 | V11: 5.4701174 | W11: 3.7787689 | X11: 2.7709398 | Y11: 3.8397839
B12: 女 | D12: 39.414732 | E12: 46.504099 | F12: 18.54735 | G12: 9.2233391 | H12: 6.6460261 | I12: 8.3821828 | J12: 10.925832 | K12: 7.3588504 | L12: 5.3119766 | M12: 3.8281094 | N12: 3.4621969 | O12: 4.3240269 | P12: 7.4045647 | Q12: 4.7176537 | R12: 5.5366109 | S12: 5.9525057 | T12: 5.494413 | U12: 40.791045 | V12: 8.1583667 | W12: 4.5475197 | X12: 9.0028576 | Y12: 17.97835
A13: 年齡
B14: 15-未滿18歲 | D14: 56.705059 | E14: 57.640242 | F14: 42.663253 | G14: 42.425393 | H14: 26.866177 | I14: 41.243074 | J14: 33.526873 | K14: 37.534316 | L14: 36.283292 | M14: 32.860097 | N14: 42.39943 | O14: 40.772275 | P14: 18.591758 | Q14: 24.455467 | R14: 23.222309 | S14: 23.044014 | T14: 52.409823 | U14: 56.112238 | V14: 33.445771 | W14: 19.07673 | X14: 40.202966 | Y14: 52.337439
B15: 18-未滿20歲 | D15: 46.604747 | E15: 49.921966 | F15: 27.585219 | G15: 17.073384 | H15: 15.917577 | I15: 7.8710604 | J15: 13.711866 | K15: 9.7811271 | L15: 39.263305 | M15: 11.75444 | N15: 7.1581753 | O15: 25.886089 | P15: 16.515416 | Q15: 71.873125 | R15: 31.386886 | S15: 2.959346 | T15: 10.379722 | U15: 54.495967 | V15: 24.621464 | W15: 10.588019 | X15: 20.200577 | Y15: 10.570344
B16: 20-未滿30歲 | D16: 32.078937 | E16: 43.767577 | F16: 14.621981 | G16: 17.870161 | H16: 3.0019168 | I16: 14.230378 | J16: 13.942343 | K16: 13.523344 | L16: 5.4892282 | M16: 4.8667637 | N16: 2.840846 | O16: 2.0990926 | P16: 0.50209883 | Q16: 3.1801684 | R16: 3.4062864 | S16: 7.6933073 | T16: 3.7031892 | U16: 46.069173 | V16: 4.5087588 | W16: 15.729003 | X16: 2.1951937 | Y16: 4.1084518
B17: 30-未滿40歲 | D17: 25.574281 | E17: 40.079386 | F17: 10.355219 | G17: 3.5011793 | H17: 8.2586958 | I17: 9.4620201 | J17: 4.4425955 | K17: 0.54928246 | L17: 1.2909368 | M17: 0.49260021 | N17: 1.8699642 | O17: 0.28663067 | P17: 0.42768467 | Q17: 0.82020711 | R17: 7.1824709 | S17: 8.237101 | T17: 4.2613287 | U17: 32.105742 | V17: 2.4963895 | W17: 0.15699545 | X17: 0.95269569 | Y17: 23.429641
B18: 40-未滿50歲 | D18: 22.085456 | E18: 32.61651 | F18: 8.9078524 | G18: 3.87797 | H18: 4.0485119 | I18: 8.4468782 | J18: 9.3742388 | K18: 3.3097807 | L18: 6.6217264 | M18: 0.37570004 | N18: 1.5132169 | O18: 2.3517414 | P18: 0 | Q18: 4.2940344 | R18: 7.3603591 | S18: 1.0181888 | T18: 1.5305421 | U18: 13.327561 | V18: 3.9591808 | W18: 0.85763442 | X18: 6.5287411 | Y18: 2.8121053
B19: 50-未滿60歲 | D19: 22.774876 | E19: 30.485232 | F19: 14.973981 | G19: 4.9049105 | H19: 1.5890962 | I19: 6.692896 | J19: 4.4329191 | K19: 6.7205009 | L19: 3.5677131 | M19: 1.7895981 | N19: 1.3773491 | O19: 0.91453598 | P19: 14.381885 | Q19: 2.330432 | R19: 3.7821445 | S19: 4.5295014 | T19: 2.8313413 | U19: 28.629808 | V19: 3.1355238 | W19: 1.5824628 | X19: 3.5302702 | Y19: 2.8231088
B20: 60-未滿65歲 | D20: 31.171946 | E20: 31.699683 | F20: 5.6675605 | G20: 10.843922 | H20: 1.494224 | I20: 5.0059849 | J20: 1.2165258 | K20: 0.93029557 | L20: 7.6820762 | M20: 1.7189871 | N20: 3.9434872 | O20: 2.582788 | P20: 4.8338371 | Q20: 0.17069804 | R20: 2.2919133 | S20: 0.74056071 | T20: 4.9081845 | U20: 20.907452 | V20: 10.597584 | W20: 5.0974352 | X20: 8.1313449 | Y20: 1.0436382
B21: 65歲及以上 | D21: 36.640963 | E21: 45.176142 | F21: 13.850301 | G21: 12.043777 | H21: 2.6812074 | I21: 12.173225 | J21: 5.6316431 | K21: 9.3989743 | L21: 8.374457 | M21: 3.4488982 | N21: 3.7690567 | O21: 4.7669398 | P21: 0.93875078 | Q21: 3.5122687 | R21: 2.9605837 | S21: 7.7792306 | T21: 10.216325 | U21: 52.392013 | V21: 11.489525 | W21: 3.1050117 | X21: 12.681184 | Y21: 2.4913864
A22: 教育程度
B23: 小學及以下 | D23: 30.193499 | E23: 37.14653 | F23: 13.056261 | G23: 8.3565233 | H23: 4.6708452 | I23: 1.5013718 | J23: 7.4891619 | K23: 4.8856029 | L23: 4.4836457 | M23: 2.7039697 | N23: 3.5599729 | O23: 3.2483545 | P23: 0.54836259 | Q23: 4.0683113 | R23: 2.0346922 | S23: 9.7524185 | T23: 12.779056 | U23: 43.817173 | V23: 6.3057943 | W23: 2.3489989 | X23: 17.994638 | Y23: 0
B24: 國(初)中 | D24: 17.182207 | E24: 38.845387 | F24: 9.930706 | G24: 4.338545 | H24: 1.5960036 | I24: 5.6258289 | J24: 7.4443641 | K24: 11.39783 | L24: 9.5617063 | M24: 2.2758728 | N24: 1.0934018 | O24: 4.1904099 | P24: 21.296996 | Q24: 2.6991647 | R24: 3.944834 | S24: 3.0850636 | T24: 2.5280109 | U24: 10.409642 | V24: 19.192067 | W24: 1.7114568 | X24: 10.677352 | Y24: 0
B25: 高中(職) | D25: 24.802113 | E25: 34.399555 | F25: 10.986037 | G25: 15.730139 | H25: 4.906625 | I25: 8.0217813 | J25: 7.4892021 | K25: 11.40372 | L25: 10.365426 | M25: 5.571938 | N25: 5.6427483 | O25: 5.875371 | P25: 1.2244005 | Q25: 4.9831498 | R25: 3.5597039 | S25: 5.1760271 | T25: 6.4685487 | U25: 33.635931 | V25: 13.312202 | W25: 5.3634597 | X25: 6.298621 | Y25: 8.8455272
B26: 專科 | D26: 27.836597 | E26: 29.202944 | F26: 14.711346 | G26: 5.8381651 | H26: 3.0062149 | I26: 10.176014 | J26: 15.134265 | K26: 11.896489 | L26: 0.99460099 | M26: 1.5123113 | N26: 0.94454802 | O26: 1.4150264 | P26: 0.72868834 | Q26: 3.8156459 | R26: 2.0170279 | S26: 1.0476613 | T26: 3.9667873 | U26: 39.87501 | V26: 5.8188095 | W26: 3.5652385 | X26: 4.7986096 | Y26: 3.7735221
B27: 大學 | D27: 30.329078 | E27: 39.206896 | F27: 13.895004 | G27: 8.2435906 | H27: 3.3401887 | I27: 14.34132 | J27: 6.7580252 | K27: 3.0132683 | L27: 4.0229878 | M27: 2.472624 | N27: 3.4193572 | O27: 3.5715373 | P27: 2.5871634 | Q27: 3.6728253 | R27: 8.4342863 | S27: 8.3380853 | T27: 4.5608369 | U27: 32.097819 | V27: 3.6337505 | W27: 5.1195266 | X27: 3.9233612 | Y27: 16.640304
B28: 研究所及以上 | D28: 38.00342 | E28: 44.762764 | F28: 14.090417 | G28: 3.6343664 | H28: 11.82346 | I28: 8.1463496 | J28: 3.8489698 | K28: 4.2285071 | L28: 11.691055 | M28: 1.1623762 | N28: 1.2615274 | O28: 0.8951714 | P28: 0 | Q28: 2.635871 | R28: 6.7100427 | S28: 0.72879028 | T28: 2.1340526 | U28: 31.655602 | V28: 4.0774716 | W28: 1.0212933 | X28: 0.93092733 | Y28: 0
B29: 不知道/無意見 | D29: 0 | E29: 0 | F29: 0 | G29: 28.201568 | H29: 0 | I29: 0 | J29: 0 | K29: 0 | L29: 0 | M29: 15.985882 | N29: 0 | O29: 0 | P29: 0 | Q29: 0 | R29: 0 | S29: 0 | T29: 40.643706 | U29: 0 | V29: 0 | W29: 0 | X29: 0 | Y29: 0
A30: 職業
B31: 農林漁牧 | D31: 32.461836 | E31: 0 | F31: 0 | G31: 0 | H31: 0 | I31: 2.1941197 | J31: 1.9464633 | K31: 0 | L31: 0 | M31: 0 | N31: 0.49686257 | O31: 0.60408831 | P31: 0 | Q31: 0 | R31: 1.6794951 | S31: 0.2964051 | T31: 3.5999302 | U31: 0 | V31: 0 | W31: 17.666072 | X31: 0 | Y31: 0
B32: 工業 | D32: 13.993909 | E32: 29.099123 | F32: 7.5795522 | G32: 7.7112551 | H32: 2.5453692 | I32: 5.4215157 | J32: 5.3463147 | K32: 2.2271836 | L32: 5.9307648 | M32: 0.56882549 | N32: 0.64645261 | O32: 2.0971742 | P32: 14.809344 | Q32: 1.5750153 | R32: 10.002737 | S32: 9.4385347 | T32: 3.0075926 | U32: 27.538566 | V32: 3.5711431 | W32: 1.6552303 | X32: 2.6075078 | Y32: 2.7373703
B33: 批發及零售業 | D33: 20.164733 | E33: 29.764633 | F33: 12.522347 | G33: 1.3362123 | H33: 1.3623505 | I33: 0.871501 | J33: 3.3292427 | K33: 7.594117 | L33: 1.3008751 | M33: 0 | N33: 0.70576193 | O33: 1.2407417 | P33: 1.0006996 | Q33: 4.9831014 | R33: 5.9283974 | S33: 7.1893671 | T33: 4.1645984 | U33: 44.977498 | V33: 2.9890501 | W33: 0.45792027 | X33: 3.1618081 | Y33: 0
B34: 住宿及餐飲業 | D34: 13.563119 | E34: 26.044578 | F34: 0 | G34: 6.5086476 | H34: 5.4699304 | I34: 4.2107032 | J34: 0.62813093 | K34: 3.5875198 | L34: 9.4610351 | M34: 3.9753237 | N34: 4.1486708 | O34: 0 | P34: 9.8467278 | Q34: 0 | R34: 1.165697 | S34: 0 | T34: 8.5653151 | U34: 14.880036 | V34: 8.214009 | W34: 18.41122 | X34: 0.48156881 | Y34: 0
B35: 服務事業 | D35: 33.044491 | E35: 38.712164 | F35: 13.002895 | G35: 5.8600348 | H35: 6.8586443 | I35: 11.465266 | J35: 6.609032 | K35: 4.1938366 | L35: 2.6780838 | M35: 2.1544684 | N35: 2.4760589 | O35: 4.5336039 | P35: 1.4038705 | Q35: 2.8681339 | R35: 3.4395736 | S35: 4.2781226 | T35: 5.0839778 | U35: 20.962775 | V35: 2.8577338 | W35: 0.63096427 | X35: 5.2032132 | Y35: 1.7124911
B36: 軍公教 | D36: 27.940773 | E36: 41.815337 | F36: 22.05625 | G36: 7.901598 | H36: 1.7986154 | I36: 9.242671 | J36: 5.6968913 | K36: 8.6291663 | L36: 11.678258 | M36: 0.71592582 | N36: 1.0815566 | O36: 1.0399583 | P36: 0 | Q36: 2.0659177 | R36: 12.762829 | S36: 1.274931 | T36: 1.1129066 | U36: 13.366846 | V36: 13.391462 | W36: 1.3859928 | X36: 0.96005177 | Y36: 13.542008
B37: 學生(部分工時就業) | D37: 21.909021 | E37: 81.356459 | F37: 40.452951 | G37: 12.965301 | H37: 16.049252 | I37: 2.0379989 | J37: 9.7763946 | K37: 16.901126 | L37: 50 | M37: 25.73145 | N37: 0 | O37: 0 | P37: 7.6857173 | Q37: 0 | R37: 0 | S37: 0 | T37: 7.4595524 | U37: 18.106513 | V37: 50 | W37: 59.37407 | X37: 0 | Y37: 0
B38: 料理家事 | D38: 35.29023 | E38: 44.953845 | F38: 9.0295779 | G38: 6.7026452 | H38: 4.9296872 | I38: 2.2137333 | J38: 22.649113 | K38: 2.7923272 | L38: 2.9454539 | M38: 5.1906637 | N38: 2.9159599 | O38: 5.7750278 | P38: 1.1426437 | Q38: 3.224694 | R38: 5.6962128 | S38: 9.3713539 | T38: 8.4545481 | U38: 51.518954 | V38: 12.65429 | W38: 5.6382186 | X38: 15.270445 | Y38: 0
B39: 退休人員 | D39: 35.936566 | E39: 37.019669 | F39: 11.365781 | G39: 16.39524 | H39: 2.7218731 | I39: 14.362378 | J39: 2.7096369 | K39: 6.6543512 | L39: 6.7001042 | M39: 3.7879057 | N39: 3.3568133 | O39: 1.4489542 | P39: 0.85071583 | Q39: 2.8273166 | R39: 3.2361209 | S39: 3.1383593 | T39: 6.7892601 | U39: 50.887686 | V39: 8.205062 | W39: 3.1819638 | X39: 9.5411371 | Y39: 5.8043935
B40: 學生 | D40: 52.9868 | E40: 58.508881 | F40: 41.721557 | G40: 32.346687 | H40: 18.237684 | I40: 38.9689 | J40: 30.896608 | K40: 37.654617 | L40: 39.366392 | M40: 33.115806 | N40: 36.473806 | O40: 22.652501 | P40: 12.654107 | Q40: 28.257259 | R40: 17.340416 | S40: 5.8272235 | T40: 34.847896 | U40: 59.334873 | V40: 24.674512 | W40: 18.803437 | X40: 14.510601 | Y40: 56.394847
B41: 未就業者 | D41: 25.382551 | E41: 33.823797 | F41: 17.537433 | G41: 2.2002149 | H41: 4.3108956 | I41: 0 | J41: 6.7894024 | K41: 3.9129042 | L41: 5.8613055 | M41: 7.5692866 | N41: 7.230594 | O41: 0.96556289 | P41: 0 | Q41: 7.0717161 | R41: 0.44810319 | S41: 12.359844 | T41: 12.595561 | U41: 62.220088 | V41: 0 | W41: 0 | X41: 11.771676 | Y41: 0
B42: 不知道/無意見 | D42: 0 | E42: 0 | F42: 0 | G42: 44.758605 | H42: 0 | I42: 0 | J42: 0 | K42: 0 | L42: 0 | M42: 0 | N42: 0 | O42: 0 | P42: 80.588682 | Q42: 0 | R42: 0 | S42: 0 | T42: 0 | U42: 0 | V42: 14.220269 | W42: 0 | X42: 0 | Y42: 0
A44: 外出目的
...

Sheet C11
E1: 附表11 | F1: 外出民眾運具次數市占率─按各運具分 | M1: 外出民眾運具次數市占率─按各運具分(續完)
F2: 《平日市話及手機》 | M2: 《平日市話及手機》
E3: 調查對象 | F3: 為昨天有外出民眾，以運具次數角度做分析。 | M3: 為昨天有外出民眾，以運具次數角度做分析。
L4: 單位：運具次數；% | T4: 單位：運具次數；%
A5: 項目別 | D5: 樣本數 | E5: 總計
F6: 公共 運輸 | M6: 非機動運具 | Q6: 私人機動運具
G7: 捷運 | H7: 高鐵 | I7: 臺鐵 | J7: 汽車 客運 | K7: 計程車 | L7: 其他公共運輸 | N7: 步行 | O7: 自行車 | P7: 微型電動二輪車 | R7: 機車 | S7: 自用 小客車 | T7: 其他私人機動運具
G8: 捷運 | H8: 高鐵 | I8: 臺鐵 | J8: 國道客運 | L8: 渡輪
A9: 全體 | D9: 70610.93 | E9: 100 | F9: 15.205768 | G9: 4.6292845 | H9: 0.55362739 | I9: 1.4059964 | J9: 5.987247 | K9: 2.5465729 | L9: 0.083039366 | M9: 12.801645 | N9: 9.9077953 | O9: 2.7335562 | P9: 0.16029348 | Q9: 71.992587 | R9: 43.708487 | S9: 26.568069 | T9: 1.7160315
A10: 居住縣市 | C10: ='C08'!C10 -> ***
B11: 新北市 | C11: ='C08'!C11 -> 0 | D11: 11825.78 | E11: 100 | F11: 29.022313 | G11: 12.327222 | H11: 0.4359269 | I11: 1.574618 | J11: 10.984754 | K11: 3.6843951 | L11: 0.015396261 | M11: 16.180043 | N11: 14.785981 | O11: 1.2798339 | P11: 0.11422814 | Q11: 54.797644 | R11: 36.181353 | S11: 17.985372 | T11: 0.63091922
B12: 臺北市 | C12: ='C08'!C12 -> 0 | D12: 7971.3183 | E12: 100 | F12: 38.331318 | G12: 15.996426 | H12: 0.42747075 | I12: 0.77065398 | J12: 13.660867 | K12: 7.3170793 | L12: 0.15882102 | M12: 24.710046 | N12: 20.849964 | O12: 3.844733 | P12: 0.01534912 | Q12: 36.958636 | R12: 20.052988 | S12: 16.315906 | T12: 0.58974226
B13: 桃園市 | C13: ='C08'!C13 -> 0 | D13: 7305.4333 | E13: 100 | F13: 12.943646 | G13: 3.2344863 | H13: 0.53516767 | I13: 1.886163 | J13: 6.1358792 | K13: 1.1519498 | L13: 0 | M13: 14.005143 | N13: 11.288199 | O13: 2.5073554 | P13: 0.20958836 | Q13: 73.051211 | R13: 42.338641 | S13: 29.334951 | T13: 1.3776188
B14: 臺中市 | C14: ='C08'!C14 -> 0 | D14: 7339.5437 | E14: 100 | F14: 9.0082473 | G14: 0.33745515 | H14: 0.12776074 | I14: 1.5664231 | J14: 4.9114744 | K14: 2.0359078 | L14: 0.02922612 | M14: 9.3891125 | N14: 7.1700761 | O14: 1.9004935 | P14: 0.31854286 | Q14: 81.60264 | R14: 48.76779 | S14: 31.432594 | T14: 1.4022558
B15: 臺南市 | C15: ='C08'!C15 -> 0 | D15: 6151.9164 | E15: 100 | F15: 4.9273885 | G15: 0.11278803 | H15: 0.5872617 | I15: 1.1007895 | J15: 1.7234347 | K15: 1.393308 | L15: 0.0098064809 | M15: 9.9964492 | N15: 5.417172 | O15: 4.152847 | P15: 0.42643018 | Q15: 85.076162 | R15: 53.095933 | S15: 29.442568 | T15: 2.5376617
B16: 高雄市 | C16: ='C08'!C16 -> 0 | D16: 9200.7959 | E16: 100 | F16: 10.190652 | G16: 1.6555466 | H16: 1.7863984 | I16: 1.7120318 | J16: 1.9278478 | K16: 2.7737225 | L16: 0.33510471 | M16: 8.6028633 | N16: 5.6413762 | O16: 2.8622939 | P16: 0.099193197 | Q16: 81.206485 | R16: 55.115981 | S16: 24.351209 | T16: 1.7392954
B17: 宜蘭縣 | C17: ='C08'!C17 -> 0 | D17: 1500.8651 | E17: 100 | F17: 8.3201713 | G17: 1.7674233 | H17: 0.060905687 | I17: 1.0572395 | J17: 4.9508114 | K17: 0.48379142 | L17: 0 | M17: 11.171989 | N17: 7.6415072 | O17: 3.402028 | P17: 0.12845376 | Q17: 80.50784 | R17: 40.613656 | S17: 38.813131 | T17: 1.0810524
B18: 新竹縣 | C18: ='C08'!C18 -> 0 | D18: 1737.1933 | E18: 100 | F18: 6.9230858 | G18: 0.23222001 | H18: 0.62183251 | I18: 1.5930693 | J18: 2.4588074 | K18: 2.0171566 | L18: 0 | M18: 10.858949 | N18: 8.0871357 | O18: 2.7581993 | P18: 0.013613522 | Q18: 82.217966 | R18: 46.261728 | S18: 34.592133 | T18: 1.3641048
B19: 苗栗縣 | C19: ='C08'!C19 -> 0 | D19: 1660.7303 | E19: 100 | F19: 6.8143924 | G19: 0.70837567 | H19: 0.17258927 | I19: 2.1921276 | J19: 3.2730952 | K19: 0.46820474 | L19: 0 | M19: 9.5460152 | N19: 6.6236491 | O19: 2.8524426 | P19: 0.069923516 | Q19: 83.639592 | R19: 42.896811 | S19: 38.98738 | T19: 1.7554017
B20: 彰化縣 | C20: ='C08'!C20 -> 0 | D20: 3032.284 | E20: 100 | F20: 3.4478565 | G20: 0.070508736 | H20: 0.085439408 | I20: 1.1030459 | J20: 2.1888625 | K20: 0 | L20: 0 | M20: 7.4566209 | N20: 3.854211 | O20: 3.5419423 | P20: 0.060467623 | Q20: 89.095523 | R20: 50.719237 | S20: 34.64474 | T20: 3.7315461
B21: 南投縣 | C21: ='C08'!C21 -> 0 | D21: 1486.6441 | E21: 100 | F21: 3.325239 | G21: 0.067599727 | H21: 0.28164855 | I21: 0.070284494 | J21: 2.5422369 | K21: 0.36346942 | L21: 0 | M21: 9.4733741 | N21: 8.1756635 | O21: 1.0796252 | P21: 0.21808546 | Q21: 87.201387 | R21: 50.439706 | S21: 31.261112 | T21: 5.5005687
B22: 雲林縣 | C22: ='C08'!C22 -> 0 | D22: 2042.8752 | E22: 100 | F22: 3.8018243 | G22: 0.023612356 | H22: 0.023612356 | I22: 0.58984347 | J22: 2.9582267 | K22: 0.16207548 | L22: 0.044453916 | M22: 9.7626788 | N22: 3.9898309 | O22: 5.5036493 | P22: 0.26919866 | Q22: 86.435497 | R22: 47.113389 | S22: 34.458396 | T22: 4.8637114
... B32: 連江縣 | C32: ='C08'!C32 -> 0 | D32: 30.505973 | E32: 100 | F32: 9.9172226 | G32: 2.6921867 | H32: 1.3592025 | I32: 0 | J32: 3.0966043 | K32: 0.34808493 | L32: 2.4211442 | M32: 15.81549 | N32: 15.81549 | O32: 0 | P32: 0 | Q32: 74.267288 | R32: 41.202127 | S32: 32.782235 | T32: 0.28292592
A33: 是否為直轄市 | C33: ***
B34: 直轄市 | D34: 49794.788 | E34: 100 | F34: 18.747203 | G34: 6.3324684 | H34: 0.67193962 | I34: 1.4572671 | J34: 6.9889203 | K34: 3.2000882 | L34: 0.096519155 | M34: 14.061496 | N34: 11.273848 | O34: 2.6093504 | P34: 0.17829781 | Q34: 67.191301 | R34: 41.946349 | S34: 23.957015 | T34: 1.2879368
B35: 非直轄市 | D35: 20816.143 | E35: 100 | F35: 6.7342169 | G35: 0.55505805 | H35: 0.27060991 | I35: 1.2833506 | J35: 3.5911208 | K35: 0.98328355 | L35: 0.050794043 | M35: 9.787925 | N35: 6.6400283 | O35: 3.0306719 | P35: 0.11722489 | Q35: 83.477858 | R35: 47.92374 | S35: 32.814031 | T35: 2.7400869
A36: 性別 | C36: ='C08'!C36 -> ***
B37: 男 | C37: ='C08'!C37 -> 0 | D37: 34519.188 | E37: 100 | F37: 11.031506 | G37: 3.2002017 | H37: 0.63869698 | I37: 1.1029961 | J37: 3.942008 | K37: 2.0318454 | L37: 0.11575794 | M37: 10.781281 | N37: 7.4937156 | O37: 3.0657114 | P37: 0.22185431 | Q37: 78.187213 | R37: 43.460911 | S37: 31.565142 | T37: 3.1611596
B38: 女 | C38: ='C08'!C38 -> 0 | D38: 36091.743 | E38: 100 | F38: 19.198152 | G38: 5.9961008 | H38: 0.47226438 | I38: 1.6957946 | J38: 7.9433728 | K38: 3.0388732 | L38: 0.051746371 | M38: 14.733979 | N38: 12.216691 | O38: 2.4158733 | P38: 0.10141492 | Q38: 66.067868 | R38: 43.945276 | S38: 21.788723 | T38: 0.33386909
A39: 年齡 | C39: ='C08'!C39 -> ***
B40: 15-未滿18歲 | C40: ='C08'!C40 -> 0 | D40: 2212.2927 | E40: 100 | F40: 43.154489 | G40: 8.3448461 | H40: 0.052284769 | I40: 4.2368841 | J40: 29.072312 | K40: 1.4334377 | L40: 0.014724434 | M40: 30.567669 | N40: 19.746052 | O40: 9.9850555 | P40: 0.83656185 | Q40: 26.277841 | R40: 14.007924 | S40: 12.162082 | T40: 0.10783527
B41: 18-未滿20歲 | C41: ='C08'!C41 -> 0 | D41: 1244.5921 | E41: 100 | F41: 27.399422 | G41: 6.3964434 | H41: 0.55804791 | I41: 3.7704085 | J41: 15.592785 | K41: 1.0817372 | L41: 0 | M41: 14.491152 | N41: 9.7731407 | O41: 4.6920909 | P41: 0.025920782 | Q41: 58.109426 | R41: 45.122987 | S41: 12.033156 | T41: 0.95328347
B42: 20-未滿30歲 | C42: ='C08'!C42 -> 0 | D42: 9701.8898 | E42: 100 | F42: 17.747568 | G42: 6.1714654 | H42: 0.7754927 | I42: 2.6730176 | J42: 5.7204331 | K42: 2.3561925 | L42: 0.050967147 | M42: 9.3151944 | N42: 7.6107166 | O42: 1.6135479 | P42: 0.09092982 | Q42: 72.937237 | R42: 52.650849 | S42: 18.825592 | T42: 1.4607956
B43: 30-未滿40歲 | C43: ='C08'!C43 -> 0 | D43: 12380.778 | E43: 100 | F43: 12.864226 | G43: 4.9615181 | H43: 0.69386392 | I43: 1.3818451 | J43: 2.8186089 | K43: 2.9934369 | L43: 0.014952755 | M43: 7.3100272 | N43: 5.8570619 | O43: 1.2961308 | P43: 0.15683447 | Q43: 79.825747 | R43: 44.809307 | S43: 33.270384 | T43: 1.7460554
B44: 40-未滿50歲 | C44: ='C08'!C44 -> 0 | D44: 15486.216 | E44: 100 | F44: 11.010597 | G44: 4.157513 | H44: 0.722009 | I44: 0.43807096 | J44: 3.9785904 | K44: 1.6824567 | L44: 0.031956526 | M44: 7.7829253 | N44: 5.989287 | O44: 1.5858657 | P44: 0.2077726 | Q44: 81.206478 | R44: 46.674108 | S44: 33.457094 | T44: 1.0752766
B45: 50-未滿60歲 | C45: ='C08'!C45 -> 0 | D45: 12901.869 | E45: 100 | F45: 11.818981 | G45: 3.8004839 | H45: 0.25740742 | I45: 1.1597856 | J45: 4.4309999 | K45: 1.9978192 | L45: 0.1724846 | M45: 9.640612 | N45: 7.6781255 | O45: 1.8231048 | P45: 0.13938172 | Q45: 78.540407 | R45: 44.680895 | S45: 31.074461 | T45: 2.7850521
B46: 60-未滿65歲 | C46: ='C08'!C46 -> 0 | D46: 5681.6279 | E46: 100 | F46: 12.848816 | G46: 2.9136039 | H46: 0.9125052 | I46: 1.2828198 | J46: 5.1559862 | K46: 2.5595997 | L46: 0.024301531 | M46: 14.4996 | N46: 10.850434 | O46: 3.6139465 | P46: 0.035219681 | Q46: 72.651584 | R46: 44.388844 | S46: 24.819748 | T46: 3.4429921
B47: 65歲及以上 | D47: 11001.665 | E47: 100 | F47: 19.693951 | G47: 4.4704189 | H47: 0.22549999 | I47: 1.1939334 | J47: 9.1413884 | K47: 4.4542891 | L47: 0.20842082 | M47: 28.187164 | N47: 22.172646 | O47: 5.8876681 | P47: 0.12685048 | Q47: 52.118885 | R47: 34.729975 | S47: 16.315489 | T47: 1.0734213
A48: 教育程度 | C48: ='C08'!C49 -> ***
B49: 小學及以下 | C49: ='C08'!C50 -> 0 | D49: 3786.5522 | E49: 100 | F49: 12.806226 | G49: 1.5882783 | H49: 0.47087837 | I49: 0.49735161 | J49: 6.6368555 | K49: 3.5451527 | L49: 0.067709261 | M49: 36.221089 | N49: 26.83057 | O49: 9.1894854 | P49: 0.20103436 | Q49: 50.972685 | R49: 40.002014 | S49: 9.2560612 | T49: 1.7146095
...

Sheet C12
E1: 附表12 | F1: 通勤學民眾運具次數市占率─按各運具分 | M1: 通勤學民眾運具次數市占率–按各運具分(續完)
F2: 《平日市話及手機》 | M2: 《平日市話及手機》
E3: 調查對象 | F3: 為昨天外出目的為通勤學民眾，以運具次數角度做分析。 | M3: 為昨天外出目的為通勤學民眾，以運具次數角度做分析。
L4: 單位：運具次數；% | T4: 單位：運具次數；%
A5: 項目別 | D5: 樣本數 | E5: 總計
F6: 公共 運輸 | M6: 非機動運具 | Q6: 私人機動運具
G7: 捷運 | H7: 高鐵 | I7: 臺鐵 | J7: 汽車 客運 | K7: 計程車 | L7: 其他公共運輸 | N7: 步行 | O7: 自行車 | P7: 微型電動二輪車 | R7: 機車 | S7: 自用 小客車 | T7: 其他私人機動運具
G8: 捷運 | H8: 高鐵 | I8: 臺鐵 | J8: 國道客運 | L8: 渡輪
A9: 全體 | D9: 35213.827 | E9: 100 | F9: 16.122391 | G9: 6.0595321 | H9: 0.30060721 | I9: 1.3617937 | J9: 7.0310711 | K9: 1.2983727 | L9: 0.07101435 | M9: 8.1961608 | N9: 6.0140261 | O9: 2.0011247 | P9: 0.18101005 | Q9: 75.681448 | R9: 46.695848 | S9: 27.225916 | T9: 1.7596848
A10: 居住縣市 | C10: ='C08'!C10 -> ***
B11: 新北市 | C11: ='C08'!C11 -> 0 | D11: 6920.0757 | E11: 100 | F11: 30.246852 | G11: 14.450555 | H11: 0.022771099 | I11: 1.6705503 | J11: 11.284336 | K11: 2.8186395 | L11: 0 | M11: 11.072769 | N11: 10.174459 | O11: 0.70310478 | P11: 0.1952055 | Q11: 58.680379 | R11: 40.92104 | S11: 17.341702 | T11: 0.4176368
B12: 臺北市 | C12: ='C08'!C12 -> 0 | D12: 4007.8581 | E12: 100 | F12: 38.873937 | G12: 20.067805 | H12: 0.16806605 | I12: 0.70663224 | J12: 15.412363 | K12: 2.5190712 | L12: 0 | M12: 18.359932 | N12: 15.041631 | O12: 3.2877731 | P12: 0.030528207 | Q12: 42.76613 | R12: 24.146634 | S12: 17.790577 | T12: 0.82891904
B13: 桃園市 | C13: ='C08'!C13 -> 0 | D13: 3877.2483 | E13: 100 | F13: 15.1373 | G13: 4.3246436 | H13: 0.34299104 | I13: 2.233581 | J13: 7.6714865 | K13: 0.56459814 | L13: 0 | M13: 8.8218663 | N13: 5.7806223 | O13: 2.8348368 | P13: 0.20640711 | Q13: 76.040833 | R13: 44.488668 | S13: 30.36206 | T13: 1.1901059
B14: 臺中市 | C14: ='C08'!C14 -> 0 | D14: 3871.2029 | E14: 100 | F14: 6.4730448 | G14: 0.31627761 | H14: 0 | I14: 0.36323718 | J14: 5.6492055 | K14: 0.14432459 | L14: 0 | M14: 5.2892633 | N14: 3.6680567 | O14: 1.3769738 | P14: 0.24423278 | Q14: 88.237692 | R14: 53.044498 | S14: 34.197569 | T14: 0.99562472
B15: 臺南市 | C15: ='C08'!C15 -> 0 | D15: 2784.792 | E15: 100 | F15: 3.3609841 | G15: 0 | H15: 0.03917084 | I15: 1.2212883 | J15: 2.0224055 | K15: 0.078119442 | L15: 0 | M15: 4.7428754 | N15: 1.1747231 | O15: 2.9919054 | P15: 0.57624689 | Q15: 91.896141 | R15: 58.922142 | S15: 30.191015 | T15: 2.7829837
B16: 高雄市 | C16: ='C08'!C16 -> 0 | D16: 4146.6655 | E16: 100 | F16: 10.617575 | G16: 2.5028033 | H16: 1.5904576 | I16: 1.4055626 | J16: 2.1885442 | K16: 2.3644784 | L16: 0.56572922 | M16: 4.3050086 | N16: 2.5117779 | O16: 1.6378314 | P16: 0.15539932 | Q16: 85.077416 | R16: 59.632476 | S16: 23.50823 | T16: 1.93671
B17: 宜蘭縣 | C17: ='C08'!C17 -> 0 | D17: 610.82686 | E17: 100 | F17: 7.9488055 | G17: 0.60677776 | H17: 0.1496516 | I17: 1.5023954 | J17: 5.3906775 | K17: 0.2993032 | L17: 0 | M17: 5.5304027 | N17: 3.4113984 | O17: 1.9152971 | P17: 0.20370717 | Q17: 86.520792 | R17: 44.371179 | S17: 40.468082 | T17: 1.6815308
B18: 新竹縣 | C18: ='C08'!C18 -> 0 | D18: 926.3587 | E18: 100 | F18: 6.9461382 | G18: 0.25690805 | H18: 0.5046315 | I18: 1.0825356 | J18: 3.0812736 | K18: 2.0207895 | L18: 0 | M18: 5.865061 | N18: 5.2488143 | O18: 0.6162467 | P18: 0 | Q18: 87.188801 | R18: 46.918573 | S18: 39.232439 | T18: 1.0377889
B19: 苗栗縣 | C19: ='C08'!C19 -> 0 | D19: 722.96353 | E19: 100 | F19: 7.9476699 | G19: 0.1123709 | H19: 0.09851935 | I19: 2.8551658 | J19: 4.8816138 | K19: 0 | L19: 0 | M19: 4.7975633 | N19: 2.1571137 | O19: 2.4798272 | P19: 0.16062235 | Q19: 87.254767 | R19: 41.735302 | S19: 42.554883 | T19: 2.9645815
B20: 彰化縣 | C20: ='C08'!C20 -> 0 | D20: 1773.0395 | E20: 100 | F20: 4.2227561 | G20: 0.080961373 | H20: 0.080961373 | I20: 1.3834338 | J20: 2.6773996 | K20: 0 | L20: 0 | M20: 4.3684244 | N20: 1.269329 | O20: 3.0990954 | P20: 0 | Q20: 91.408819 | R20: 52.786011 | S20: 35.660575 | T20: 2.9622335
B21: 南投縣 | C21: ='C08'!C21 -> 0 | D21: 602.60151 | E21: 100 | F21: 3.5357018 | G21: 0 | H21: 0.18392765 | I21: 0.061411615 | J21: 3.0134326 | K21: 0.27692991 | L21: 0 | M21: 4.8127157 | N21: 4.534013 | O21: 0.1854997 | P21: 0.093202959 | Q21: 91.651583 | R21: 47.572502 | S21: 35.735584 | T21: 8.343496
B22: 雲林縣 | C22: ='C08'!C22 -> 0 | D22: 866.42198 | E22: 100 | F22: 6.1565885 | G22: 0 | H22: 0 | I22: 0.75597946 | J22: 5.4006091 | K22: 0 | L22: 0 | M22: 6.6545691 | N22: 1.2201546 | O22: 5.2287764 | P22: 0.20563806 | Q22: 87.188842 | R22: 46.760022 | S22: 34.909697 | T22: 5.5191228
